WARNING Not Found: /sem4/
WARNING "GET /sem4/ HTTP/1.1" 404 2772
WARNING Not Found: /favicon.ico
WARNING "GET /favicon.ico HTTP/1.1" 404 2714
WARNING Not Found: /sem4/choise_form
WARNING "GET /sem4/choise_form HTTP/1.1" 404 2805
WARNING Not Found: /sem4/choise_form/
WARNING "GET /sem4/choise_form/ HTTP/1.1" 404 2808
WARNING Not Found: /sem4/user/add/choise_form/
WARNING "GET /sem4/user/add/choise_form/ HTTP/1.1" 404 2835
ERROR Internal Server Error: /sem4/user/add/
Traceback (most recent call last):
  File "C:\Users\kapa-\PycharmProjects\pythonDjango\venv\Lib\site-packages\django\template\backends\django.py", line 61, in render
    return self.template.render(context)
           ^^^^^^^^^^^^^^^^^^^^^^^^^^^^^
  File "C:\Users\kapa-\PycharmProjects\pythonDjango\venv\Lib\site-packages\django\template\base.py", line 175, in render
    return self._render(context)
           ^^^^^^^^^^^^^^^^^^^^^
  File "C:\Users\kapa-\PycharmProjects\pythonDjango\venv\Lib\site-packages\django\template\base.py", line 167, in _render
    return self.nodelist.render(context)
           ^^^^^^^^^^^^^^^^^^^^^^^^^^^^^
  File "C:\Users\kapa-\PycharmProjects\pythonDjango\venv\Lib\site-packages\django\template\base.py", line 1005, in render
    return SafeString("".join([node.render_annotated(context) for node in self]))
                              ^^^^^^^^^^^^^^^^^^^^^^^^^^^^^^^^^^^^^^^^^^^^^^^^^
  File "C:\Users\kapa-\PycharmProjects\pythonDjango\venv\Lib\site-packages\django\template\base.py", line 1005, in <listcomp>
    return SafeString("".join([node.render_annotated(context) for node in self]))
                               ^^^^^^^^^^^^^^^^^^^^^^^^^^^^^^
  File "C:\Users\kapa-\PycharmProjects\pythonDjango\venv\Lib\site-packages\django\template\base.py", line 966, in render_annotated
    return self.render(context)
           ^^^^^^^^^^^^^^^^^^^^
  File "C:\Users\kapa-\PycharmProjects\pythonDjango\venv\Lib\site-packages\django\template\loader_tags.py", line 132, in render
    compiled_parent = self.get_parent(context)
                      ^^^^^^^^^^^^^^^^^^^^^^^^
  File "C:\Users\kapa-\PycharmProjects\pythonDjango\venv\Lib\site-packages\django\template\loader_tags.py", line 129, in get_parent
    return self.find_template(parent, context)
           ^^^^^^^^^^^^^^^^^^^^^^^^^^^^^^^^^^^
  File "C:\Users\kapa-\PycharmProjects\pythonDjango\venv\Lib\site-packages\django\template\loader_tags.py", line 107, in find_template
    template, origin = context.template.engine.find_template(
                       ^^^^^^^^^^^^^^^^^^^^^^^^^^^^^^^^^^^^^^
  File "C:\Users\kapa-\PycharmProjects\pythonDjango\venv\Lib\site-packages\django\template\engine.py", line 161, in find_template
    raise TemplateDoesNotExist(name, tried=tried)
django.template.exceptions.TemplateDoesNotExist: base_temp.html

The above exception was the direct cause of the following exception:

Traceback (most recent call last):
  File "C:\Users\kapa-\PycharmProjects\pythonDjango\venv\Lib\site-packages\django\core\handlers\exception.py", line 55, in inner
    response = get_response(request)
               ^^^^^^^^^^^^^^^^^^^^^
  File "C:\Users\kapa-\PycharmProjects\pythonDjango\venv\Lib\site-packages\django\core\handlers\base.py", line 197, in _get_response
    response = wrapped_callback(request, *callback_args, **callback_kwargs)
               ^^^^^^^^^^^^^^^^^^^^^^^^^^^^^^^^^^^^^^^^^^^^^^^^^^^^^^^^^^^^
  File "C:\Users\kapa-\PycharmProjects\pythonDjango\django_S_1\s4app\views.py", line 38, in choice_form
    return render(request, 's4app/choice_form.html', {'form': form})
           ^^^^^^^^^^^^^^^^^^^^^^^^^^^^^^^^^^^^^^^^^^^^^^^^^^^^^^^^^
  File "C:\Users\kapa-\PycharmProjects\pythonDjango\venv\Lib\site-packages\django\shortcuts.py", line 24, in render
    content = loader.render_to_string(template_name, context, request, using=using)
              ^^^^^^^^^^^^^^^^^^^^^^^^^^^^^^^^^^^^^^^^^^^^^^^^^^^^^^^^^^^^^^^^^^^^^
  File "C:\Users\kapa-\PycharmProjects\pythonDjango\venv\Lib\site-packages\django\template\loader.py", line 62, in render_to_string
    return template.render(context, request)
           ^^^^^^^^^^^^^^^^^^^^^^^^^^^^^^^^^
  File "C:\Users\kapa-\PycharmProjects\pythonDjango\venv\Lib\site-packages\django\template\backends\django.py", line 63, in render
    reraise(exc, self.backend)
  File "C:\Users\kapa-\PycharmProjects\pythonDjango\venv\Lib\site-packages\django\template\backends\django.py", line 84, in reraise
    raise new from exc
django.template.exceptions.TemplateDoesNotExist: base_temp.html
ERROR "GET /sem4/user/add/ HTTP/1.1" 500 133213
WARNING Not Found: /sem4/choice_form/
WARNING "GET /sem4/choice_form/ HTTP/1.1" 404 2808
WARNING Not Found: /sem4/choice_form
WARNING "GET /sem4/choice_form HTTP/1.1" 404 2805
WARNING Not Found: /sem4/
WARNING "GET /sem4/ HTTP/1.1" 404 2772
WARNING Not Found: /sem4
WARNING "GET /sem4 HTTP/1.1" 404 2693
INFO C:\Users\kapa-\PycharmProjects\pythonDjango\django_S_1\s4app\urls.py changed, reloading.
INFO C:\Users\kapa-\PycharmProjects\pythonDjango\django_S_1\s4app\urls.py changed, reloading.
ERROR Internal Server Error: /sem4/choice/
Traceback (most recent call last):
  File "C:\Users\kapa-\PycharmProjects\pythonDjango\venv\Lib\site-packages\django\template\backends\django.py", line 61, in render
    return self.template.render(context)
           ^^^^^^^^^^^^^^^^^^^^^^^^^^^^^
  File "C:\Users\kapa-\PycharmProjects\pythonDjango\venv\Lib\site-packages\django\template\base.py", line 175, in render
    return self._render(context)
           ^^^^^^^^^^^^^^^^^^^^^
  File "C:\Users\kapa-\PycharmProjects\pythonDjango\venv\Lib\site-packages\django\template\base.py", line 167, in _render
    return self.nodelist.render(context)
           ^^^^^^^^^^^^^^^^^^^^^^^^^^^^^
  File "C:\Users\kapa-\PycharmProjects\pythonDjango\venv\Lib\site-packages\django\template\base.py", line 1005, in render
    return SafeString("".join([node.render_annotated(context) for node in self]))
                              ^^^^^^^^^^^^^^^^^^^^^^^^^^^^^^^^^^^^^^^^^^^^^^^^^
  File "C:\Users\kapa-\PycharmProjects\pythonDjango\venv\Lib\site-packages\django\template\base.py", line 1005, in <listcomp>
    return SafeString("".join([node.render_annotated(context) for node in self]))
                               ^^^^^^^^^^^^^^^^^^^^^^^^^^^^^^
  File "C:\Users\kapa-\PycharmProjects\pythonDjango\venv\Lib\site-packages\django\template\base.py", line 966, in render_annotated
    return self.render(context)
           ^^^^^^^^^^^^^^^^^^^^
  File "C:\Users\kapa-\PycharmProjects\pythonDjango\venv\Lib\site-packages\django\template\loader_tags.py", line 132, in render
    compiled_parent = self.get_parent(context)
                      ^^^^^^^^^^^^^^^^^^^^^^^^
  File "C:\Users\kapa-\PycharmProjects\pythonDjango\venv\Lib\site-packages\django\template\loader_tags.py", line 129, in get_parent
    return self.find_template(parent, context)
           ^^^^^^^^^^^^^^^^^^^^^^^^^^^^^^^^^^^
  File "C:\Users\kapa-\PycharmProjects\pythonDjango\venv\Lib\site-packages\django\template\loader_tags.py", line 107, in find_template
    template, origin = context.template.engine.find_template(
                       ^^^^^^^^^^^^^^^^^^^^^^^^^^^^^^^^^^^^^^
  File "C:\Users\kapa-\PycharmProjects\pythonDjango\venv\Lib\site-packages\django\template\engine.py", line 161, in find_template
    raise TemplateDoesNotExist(name, tried=tried)
django.template.exceptions.TemplateDoesNotExist: base_temp.html

The above exception was the direct cause of the following exception:

Traceback (most recent call last):
  File "C:\Users\kapa-\PycharmProjects\pythonDjango\venv\Lib\site-packages\django\core\handlers\exception.py", line 55, in inner
    response = get_response(request)
               ^^^^^^^^^^^^^^^^^^^^^
  File "C:\Users\kapa-\PycharmProjects\pythonDjango\venv\Lib\site-packages\django\core\handlers\base.py", line 197, in _get_response
    response = wrapped_callback(request, *callback_args, **callback_kwargs)
               ^^^^^^^^^^^^^^^^^^^^^^^^^^^^^^^^^^^^^^^^^^^^^^^^^^^^^^^^^^^^
  File "C:\Users\kapa-\PycharmProjects\pythonDjango\django_S_1\s4app\views.py", line 38, in choice_form
    return render(request, 's4app/choice_form.html', {'form': form})
           ^^^^^^^^^^^^^^^^^^^^^^^^^^^^^^^^^^^^^^^^^^^^^^^^^^^^^^^^^
  File "C:\Users\kapa-\PycharmProjects\pythonDjango\venv\Lib\site-packages\django\shortcuts.py", line 24, in render
    content = loader.render_to_string(template_name, context, request, using=using)
              ^^^^^^^^^^^^^^^^^^^^^^^^^^^^^^^^^^^^^^^^^^^^^^^^^^^^^^^^^^^^^^^^^^^^^
  File "C:\Users\kapa-\PycharmProjects\pythonDjango\venv\Lib\site-packages\django\template\loader.py", line 62, in render_to_string
    return template.render(context, request)
           ^^^^^^^^^^^^^^^^^^^^^^^^^^^^^^^^^
  File "C:\Users\kapa-\PycharmProjects\pythonDjango\venv\Lib\site-packages\django\template\backends\django.py", line 63, in render
    reraise(exc, self.backend)
  File "C:\Users\kapa-\PycharmProjects\pythonDjango\venv\Lib\site-packages\django\template\backends\django.py", line 84, in reraise
    raise new from exc
django.template.exceptions.TemplateDoesNotExist: base_temp.html
ERROR "GET /sem4/choice/ HTTP/1.1" 500 133185
ERROR Internal Server Error: /sem4/choice/
Traceback (most recent call last):
  File "C:\Users\kapa-\PycharmProjects\pythonDjango\venv\Lib\site-packages\django\template\backends\django.py", line 61, in render
    return self.template.render(context)
           ^^^^^^^^^^^^^^^^^^^^^^^^^^^^^
  File "C:\Users\kapa-\PycharmProjects\pythonDjango\venv\Lib\site-packages\django\template\base.py", line 175, in render
    return self._render(context)
           ^^^^^^^^^^^^^^^^^^^^^
  File "C:\Users\kapa-\PycharmProjects\pythonDjango\venv\Lib\site-packages\django\template\base.py", line 167, in _render
    return self.nodelist.render(context)
           ^^^^^^^^^^^^^^^^^^^^^^^^^^^^^
  File "C:\Users\kapa-\PycharmProjects\pythonDjango\venv\Lib\site-packages\django\template\base.py", line 1005, in render
    return SafeString("".join([node.render_annotated(context) for node in self]))
                              ^^^^^^^^^^^^^^^^^^^^^^^^^^^^^^^^^^^^^^^^^^^^^^^^^
  File "C:\Users\kapa-\PycharmProjects\pythonDjango\venv\Lib\site-packages\django\template\base.py", line 1005, in <listcomp>
    return SafeString("".join([node.render_annotated(context) for node in self]))
                               ^^^^^^^^^^^^^^^^^^^^^^^^^^^^^^
  File "C:\Users\kapa-\PycharmProjects\pythonDjango\venv\Lib\site-packages\django\template\base.py", line 966, in render_annotated
    return self.render(context)
           ^^^^^^^^^^^^^^^^^^^^
  File "C:\Users\kapa-\PycharmProjects\pythonDjango\venv\Lib\site-packages\django\template\loader_tags.py", line 132, in render
    compiled_parent = self.get_parent(context)
                      ^^^^^^^^^^^^^^^^^^^^^^^^
  File "C:\Users\kapa-\PycharmProjects\pythonDjango\venv\Lib\site-packages\django\template\loader_tags.py", line 129, in get_parent
    return self.find_template(parent, context)
           ^^^^^^^^^^^^^^^^^^^^^^^^^^^^^^^^^^^
  File "C:\Users\kapa-\PycharmProjects\pythonDjango\venv\Lib\site-packages\django\template\loader_tags.py", line 107, in find_template
    template, origin = context.template.engine.find_template(
                       ^^^^^^^^^^^^^^^^^^^^^^^^^^^^^^^^^^^^^^
  File "C:\Users\kapa-\PycharmProjects\pythonDjango\venv\Lib\site-packages\django\template\engine.py", line 161, in find_template
    raise TemplateDoesNotExist(name, tried=tried)
django.template.exceptions.TemplateDoesNotExist: base.html

The above exception was the direct cause of the following exception:

Traceback (most recent call last):
  File "C:\Users\kapa-\PycharmProjects\pythonDjango\venv\Lib\site-packages\django\core\handlers\exception.py", line 55, in inner
    response = get_response(request)
               ^^^^^^^^^^^^^^^^^^^^^
  File "C:\Users\kapa-\PycharmProjects\pythonDjango\venv\Lib\site-packages\django\core\handlers\base.py", line 197, in _get_response
    response = wrapped_callback(request, *callback_args, **callback_kwargs)
               ^^^^^^^^^^^^^^^^^^^^^^^^^^^^^^^^^^^^^^^^^^^^^^^^^^^^^^^^^^^^
  File "C:\Users\kapa-\PycharmProjects\pythonDjango\django_S_1\s4app\views.py", line 38, in choice_form
    return render(request, 's4app/choice_form.html', {'form': form})
           ^^^^^^^^^^^^^^^^^^^^^^^^^^^^^^^^^^^^^^^^^^^^^^^^^^^^^^^^^
  File "C:\Users\kapa-\PycharmProjects\pythonDjango\venv\Lib\site-packages\django\shortcuts.py", line 24, in render
    content = loader.render_to_string(template_name, context, request, using=using)
              ^^^^^^^^^^^^^^^^^^^^^^^^^^^^^^^^^^^^^^^^^^^^^^^^^^^^^^^^^^^^^^^^^^^^^
  File "C:\Users\kapa-\PycharmProjects\pythonDjango\venv\Lib\site-packages\django\template\loader.py", line 62, in render_to_string
    return template.render(context, request)
           ^^^^^^^^^^^^^^^^^^^^^^^^^^^^^^^^^
  File "C:\Users\kapa-\PycharmProjects\pythonDjango\venv\Lib\site-packages\django\template\backends\django.py", line 63, in render
    reraise(exc, self.backend)
  File "C:\Users\kapa-\PycharmProjects\pythonDjango\venv\Lib\site-packages\django\template\backends\django.py", line 84, in reraise
    raise new from exc
django.template.exceptions.TemplateDoesNotExist: base.html
ERROR "GET /sem4/choice/ HTTP/1.1" 500 133172
INFO "GET /sem4/choice HTTP/1.1" 301 0
ERROR Internal Server Error: /sem4/choice/
Traceback (most recent call last):
  File "C:\Users\kapa-\PycharmProjects\pythonDjango\venv\Lib\site-packages\django\template\backends\django.py", line 61, in render
    return self.template.render(context)
           ^^^^^^^^^^^^^^^^^^^^^^^^^^^^^
  File "C:\Users\kapa-\PycharmProjects\pythonDjango\venv\Lib\site-packages\django\template\base.py", line 175, in render
    return self._render(context)
           ^^^^^^^^^^^^^^^^^^^^^
  File "C:\Users\kapa-\PycharmProjects\pythonDjango\venv\Lib\site-packages\django\template\base.py", line 167, in _render
    return self.nodelist.render(context)
           ^^^^^^^^^^^^^^^^^^^^^^^^^^^^^
  File "C:\Users\kapa-\PycharmProjects\pythonDjango\venv\Lib\site-packages\django\template\base.py", line 1005, in render
    return SafeString("".join([node.render_annotated(context) for node in self]))
                              ^^^^^^^^^^^^^^^^^^^^^^^^^^^^^^^^^^^^^^^^^^^^^^^^^
  File "C:\Users\kapa-\PycharmProjects\pythonDjango\venv\Lib\site-packages\django\template\base.py", line 1005, in <listcomp>
    return SafeString("".join([node.render_annotated(context) for node in self]))
                               ^^^^^^^^^^^^^^^^^^^^^^^^^^^^^^
  File "C:\Users\kapa-\PycharmProjects\pythonDjango\venv\Lib\site-packages\django\template\base.py", line 966, in render_annotated
    return self.render(context)
           ^^^^^^^^^^^^^^^^^^^^
  File "C:\Users\kapa-\PycharmProjects\pythonDjango\venv\Lib\site-packages\django\template\loader_tags.py", line 132, in render
    compiled_parent = self.get_parent(context)
                      ^^^^^^^^^^^^^^^^^^^^^^^^
  File "C:\Users\kapa-\PycharmProjects\pythonDjango\venv\Lib\site-packages\django\template\loader_tags.py", line 129, in get_parent
    return self.find_template(parent, context)
           ^^^^^^^^^^^^^^^^^^^^^^^^^^^^^^^^^^^
  File "C:\Users\kapa-\PycharmProjects\pythonDjango\venv\Lib\site-packages\django\template\loader_tags.py", line 107, in find_template
    template, origin = context.template.engine.find_template(
                       ^^^^^^^^^^^^^^^^^^^^^^^^^^^^^^^^^^^^^^
  File "C:\Users\kapa-\PycharmProjects\pythonDjango\venv\Lib\site-packages\django\template\engine.py", line 161, in find_template
    raise TemplateDoesNotExist(name, tried=tried)
django.template.exceptions.TemplateDoesNotExist: base.html

The above exception was the direct cause of the following exception:

Traceback (most recent call last):
  File "C:\Users\kapa-\PycharmProjects\pythonDjango\venv\Lib\site-packages\django\core\handlers\exception.py", line 55, in inner
    response = get_response(request)
               ^^^^^^^^^^^^^^^^^^^^^
  File "C:\Users\kapa-\PycharmProjects\pythonDjango\venv\Lib\site-packages\django\core\handlers\base.py", line 197, in _get_response
    response = wrapped_callback(request, *callback_args, **callback_kwargs)
               ^^^^^^^^^^^^^^^^^^^^^^^^^^^^^^^^^^^^^^^^^^^^^^^^^^^^^^^^^^^^
  File "C:\Users\kapa-\PycharmProjects\pythonDjango\django_S_1\s4app\views.py", line 38, in choice_form
    return render(request, 's4app/choice_form.html', {'form': form})
           ^^^^^^^^^^^^^^^^^^^^^^^^^^^^^^^^^^^^^^^^^^^^^^^^^^^^^^^^^
  File "C:\Users\kapa-\PycharmProjects\pythonDjango\venv\Lib\site-packages\django\shortcuts.py", line 24, in render
    content = loader.render_to_string(template_name, context, request, using=using)
              ^^^^^^^^^^^^^^^^^^^^^^^^^^^^^^^^^^^^^^^^^^^^^^^^^^^^^^^^^^^^^^^^^^^^^
  File "C:\Users\kapa-\PycharmProjects\pythonDjango\venv\Lib\site-packages\django\template\loader.py", line 62, in render_to_string
    return template.render(context, request)
           ^^^^^^^^^^^^^^^^^^^^^^^^^^^^^^^^^
  File "C:\Users\kapa-\PycharmProjects\pythonDjango\venv\Lib\site-packages\django\template\backends\django.py", line 63, in render
    reraise(exc, self.backend)
  File "C:\Users\kapa-\PycharmProjects\pythonDjango\venv\Lib\site-packages\django\template\backends\django.py", line 84, in reraise
    raise new from exc
django.template.exceptions.TemplateDoesNotExist: base.html
ERROR "GET /sem4/choice/ HTTP/1.1" 500 133035
INFO C:\Users\kapa-\PycharmProjects\pythonDjango\django_S_1\django_S_1\settings.py changed, reloading.
INFO "GET /sem4/choice/ HTTP/1.1" 200 838
ERROR Internal Server Error: /sem4/choice/
Traceback (most recent call last):
  File "C:\Users\kapa-\PycharmProjects\pythonDjango\venv\Lib\site-packages\django\template\backends\django.py", line 61, in render
    return self.template.render(context)
           ^^^^^^^^^^^^^^^^^^^^^^^^^^^^^
  File "C:\Users\kapa-\PycharmProjects\pythonDjango\venv\Lib\site-packages\django\template\base.py", line 175, in render
    return self._render(context)
           ^^^^^^^^^^^^^^^^^^^^^
  File "C:\Users\kapa-\PycharmProjects\pythonDjango\venv\Lib\site-packages\django\template\base.py", line 167, in _render
    return self.nodelist.render(context)
           ^^^^^^^^^^^^^^^^^^^^^^^^^^^^^
  File "C:\Users\kapa-\PycharmProjects\pythonDjango\venv\Lib\site-packages\django\template\base.py", line 1005, in render
    return SafeString("".join([node.render_annotated(context) for node in self]))
                              ^^^^^^^^^^^^^^^^^^^^^^^^^^^^^^^^^^^^^^^^^^^^^^^^^
  File "C:\Users\kapa-\PycharmProjects\pythonDjango\venv\Lib\site-packages\django\template\base.py", line 1005, in <listcomp>
    return SafeString("".join([node.render_annotated(context) for node in self]))
                               ^^^^^^^^^^^^^^^^^^^^^^^^^^^^^^
  File "C:\Users\kapa-\PycharmProjects\pythonDjango\venv\Lib\site-packages\django\template\base.py", line 966, in render_annotated
    return self.render(context)
           ^^^^^^^^^^^^^^^^^^^^
  File "C:\Users\kapa-\PycharmProjects\pythonDjango\venv\Lib\site-packages\django\template\loader_tags.py", line 132, in render
    compiled_parent = self.get_parent(context)
                      ^^^^^^^^^^^^^^^^^^^^^^^^
  File "C:\Users\kapa-\PycharmProjects\pythonDjango\venv\Lib\site-packages\django\template\loader_tags.py", line 129, in get_parent
    return self.find_template(parent, context)
           ^^^^^^^^^^^^^^^^^^^^^^^^^^^^^^^^^^^
  File "C:\Users\kapa-\PycharmProjects\pythonDjango\venv\Lib\site-packages\django\template\loader_tags.py", line 107, in find_template
    template, origin = context.template.engine.find_template(
                       ^^^^^^^^^^^^^^^^^^^^^^^^^^^^^^^^^^^^^^
  File "C:\Users\kapa-\PycharmProjects\pythonDjango\venv\Lib\site-packages\django\template\engine.py", line 161, in find_template
    raise TemplateDoesNotExist(name, tried=tried)
django.template.exceptions.TemplateDoesNotExist: base_temp.html

The above exception was the direct cause of the following exception:

Traceback (most recent call last):
  File "C:\Users\kapa-\PycharmProjects\pythonDjango\venv\Lib\site-packages\django\core\handlers\exception.py", line 55, in inner
    response = get_response(request)
               ^^^^^^^^^^^^^^^^^^^^^
  File "C:\Users\kapa-\PycharmProjects\pythonDjango\venv\Lib\site-packages\django\core\handlers\base.py", line 197, in _get_response
    response = wrapped_callback(request, *callback_args, **callback_kwargs)
               ^^^^^^^^^^^^^^^^^^^^^^^^^^^^^^^^^^^^^^^^^^^^^^^^^^^^^^^^^^^^
  File "C:\Users\kapa-\PycharmProjects\pythonDjango\django_S_1\s4app\views.py", line 32, in choice_form
    return dice(request, quant)
           ^^^^^^^^^^^^^^^^^^^^
  File "C:\Users\kapa-\PycharmProjects\pythonDjango\django_S_1\s4app\views.py", line 66, in dice
    return render(request, 'playya.html', context)
           ^^^^^^^^^^^^^^^^^^^^^^^^^^^^^^^^^^^^^^^
  File "C:\Users\kapa-\PycharmProjects\pythonDjango\venv\Lib\site-packages\django\shortcuts.py", line 24, in render
    content = loader.render_to_string(template_name, context, request, using=using)
              ^^^^^^^^^^^^^^^^^^^^^^^^^^^^^^^^^^^^^^^^^^^^^^^^^^^^^^^^^^^^^^^^^^^^^
  File "C:\Users\kapa-\PycharmProjects\pythonDjango\venv\Lib\site-packages\django\template\loader.py", line 62, in render_to_string
    return template.render(context, request)
           ^^^^^^^^^^^^^^^^^^^^^^^^^^^^^^^^^
  File "C:\Users\kapa-\PycharmProjects\pythonDjango\venv\Lib\site-packages\django\template\backends\django.py", line 63, in render
    reraise(exc, self.backend)
  File "C:\Users\kapa-\PycharmProjects\pythonDjango\venv\Lib\site-packages\django\template\backends\django.py", line 84, in reraise
    raise new from exc
django.template.exceptions.TemplateDoesNotExist: base_temp.html
ERROR "POST /sem4/choice/ HTTP/1.1" 500 137742
